<?xml version="1.0" ?>
<robot name="v6_vis_URDF">

<material name="silver">
  <color rgba="0.700 0.700 0.700 1.000"/>
</material>

<link name="base_link">
  <inertial>
    <origin xyz="0.0 0.0 0.0" rpy="0 0 0"/>
    <mass value="0.04221019889999999"/>
    <inertia ixx="3.251890498292543e-06" iyy="1.2538134256292538e-05" izz="1.520270663714999e-05" ixy="-3.8369307731045404e-21" iyz="9.592326932761351e-22" ixz="0.0"/>
  </inertial>
  <visual>
    <origin xyz="0 0 0" rpy="0 0 0"/>
    <geometry>
      <mesh filename="meshes/base_link.stl" scale="0.001 0.001 0.001"/>
    </geometry>
    <material name="silver"/>
    <material/>
  </visual>
  <!-- <collision>
    <origin xyz="0 0 0" rpy="0 0 0"/>
    <geometry>
      <mesh filename="meshes/base_link.stl" scale="0.001 0.001 0.001"/>
    </geometry>
  </collision> -->
</link>

<link name="body_1">
  <inertial>
    <origin xyz="0.000491789842013503 -1.0255883859825846e-05 0.11038893514718033" rpy="0 0 0"/>
    <mass value="8.082925081618875"/>
    <inertia ixx="0.17235001335476036" iyy="0.11140096527849516" izz="0.08859656647789095" ixy="3.3933676640050195e-06" iyz="2.2245909106547117e-06" ixz="3.870150802982305e-05"/>
  </inertial>
  <visual>
    <origin xyz="-0.0 -0.0 0.005" rpy="0 0 0"/>
    <geometry>
      <mesh filename="meshes/body_1.stl" scale="0.001 0.001 0.001"/>
    </geometry>
    <material name="silver"/>
    <material/>
  </visual>
  <collision>
    <origin xyz="0 0 0.1749" rpy="0 0 0"/>
    <geometry>
       <box size="0.160 0.300 0.365"/>
    </geometry>
  </collision>
</link>

<link name="0_hip_L_1">
  <inertial>
    <origin xyz="-6.189197686711422e-18 0.081816 -0.073193" rpy="0 0 0"/>
    <mass value="2.933346061764052"/>
    <inertia ixx="0.01279960226102321" iyy="0.005775709978980612" izz="0.011136701430931525" ixy="-2.7825423557381678e-08" iyz="0.0028585589664278446" ixz="3.7158548621655364e-08"/>
  </inertial>
  <visual>
    <origin xyz="-0.0 -0.09 0.0054" rpy="0 0 0"/>
    <geometry>
      <mesh filename="meshes/0_hip_L_1.stl" scale="0.001 0.001 0.001"/>
    </geometry>
    <material name="silver"/>
    <material/>
  </visual>
  <!-- <collision>
    <origin xyz="0.0 -0.09 0.0054" rpy="0 0 0"/>
    <geometry>
      <mesh filename="meshes/0_hip_L_1.stl" scale="0.001 0.001 0.001"/>
    </geometry>
  </collision> -->
</link>

<link name="1_hip_L_1">
  <inertial>
    <origin xyz="0 -0.078238 -0.00696" rpy="0 0 0"/>
    <mass value="2.145505480911724"/>
    <inertia ixx="0.004323629600409815" iyy="0.0025840366640133457" izz="0.003607102700862279" ixy="4.633799587950194e-06" iyz="9.704839890045669e-08" ixz="2.530890915338727e-07"/>
  </inertial>
  <visual>
    <origin xyz="0.0 -0.168 0.093" rpy="0 0 0"/>
    <geometry>
      <mesh filename="meshes/1_hip_L_1.stl" scale="0.001 0.001 0.001"/>
    </geometry>
    <material name="silver"/>
    <material/>
  </visual>
  <!-- <collision>
    <origin xyz="0.0 -0.168 0.093" rpy="0 0 0"/>
    <geometry>
      <mesh filename="meshes/1_hip_L_1.stl" scale="0.001 0.001 0.001"/>
    </geometry>
  </collision> -->
</link>

<link name="2_hip_L_1">
  <inertial>
    <origin xyz="-0.032881 -0.019651 -0.188957" rpy="0 0 0"/>
    <mass value="3.718848384611402"/>
    <inertia ixx="0.02749712434541124" iyy="0.02935848197191171" izz="0.005306695420010426" ixy="-0.0002054579871883359" iyz="-0.001262426549573592" ixz="-0.002425744845437923"/>
  </inertial>
  <visual>
    <origin xyz="-0.0272 -0.0902 0.093" rpy="0 0 0"/>
    <geometry>
      <mesh filename="meshes/2_hip_L_1.stl" scale="0.001 0.001 0.001"/>
    </geometry>
    <material name="silver"/>
    <material/>
  </visual>
  <collision>
    <origin xyz="-0.0272 -0.02 -0.205" rpy="0 0 0"/>
    <geometry>
      <box size="0.12 0.08 0.27"/>
    </geometry>
  </collision>
</link>

<link name="3_knee_L_1">
  <inertial>
    <origin xyz="0.020174 -0.011965 -0.118449" rpy="0 0 0"/>
    <mass value="1.008967649963129"/>
    <inertia ixx="0.007304699903664141" iyy="0.009688584293469443" izz="0.002487274385998401" ixy="8.906478202698942e-07" iyz="-2.7631243961649676e-05" ixz="0.0017826690415986435"/>
  </inertial>
  <visual>
    <origin xyz="0.0 -0.0829 0.373" rpy="0 0 0"/>
    <geometry>
      <mesh filename="meshes/3_knee_L_1.stl" scale="0.001 0.001 0.001"/>
    </geometry>
    <material name="silver"/>
    <material/>
  </visual>
  <!-- <collision>
    <origin xyz="0.0 -0.0829 0.373" rpy="0 0 0"/>
    <geometry>
      <mesh filename="meshes/3_knee_L_1.stl" scale="0.001 0.001 0.001"/>
    </geometry>
  </collision> -->
</link>

<link name="4_foot_L_simple_1">
  <inertial>
    <origin xyz="0.04057 0 -0.028042" rpy="0 0 0"/>
    <mass value="0.24221050463757302"/>
    <inertia ixx="4.71711257565427e-05" iyy="0.00054163513919947" izz="0.0005455651932004392" ixy="0" iyz="0" ixz="1.0205724243504688e-05"/>
  </inertial>
 <visual>
    <origin xyz="0.0 -0.0902 0.608" rpy="0 0 0"/>
    <geometry>
      <mesh filename="meshes/4_foot_L_aug10_1.stl" scale="0.001 0.001 0.001"/>
    </geometry>
    <material name="silver"/>
    <material/>
  </visual>
  <collision>
    <origin xyz="0.0 -0.0902 0.608" rpy="0 0 0"/>
    <geometry>
      <mesh filename="meshes/4_foot_L_aug10_1.stl" scale="0.001 0.001 0.001"/>
    </geometry>
  </collision>
</link>


<link name="5_hip_R_1">
  <inertial>
    <origin xyz="-6.189197686711422e-18 -0.081816 -0.073193" rpy="0 0 0"/>
    <mass value="2.933346061764052"/>
    <inertia ixx="0.01279960226102321" iyy="0.005775709978980612" izz="0.011136701430931525" ixy="2.7825423557381678e-08" iyz="-0.0028585589664278446" ixz="3.7158548621655364e-08"/>
  </inertial>
  <visual>
    <origin xyz="0.0 0.09 0.0054" rpy="0 0 0"/>
    <geometry>
      <mesh filename="meshes/5_hip_R_1.stl" scale="0.001 0.001 0.001"/>
    </geometry>
    <material name="silver"/>
    <material/>
  </visual>
  <!-- <collision>
    <origin xyz="0.0 0.09 0.0054" rpy="0 0 0"/>
    <geometry>
      <mesh filename="meshes/5_hip_R_1.stl" scale="0.001 0.001 0.001"/>
    </geometry>
  </collision> -->
</link>

<link name="6_hip_R_1">
  <inertial>
    <origin xyz="0 0.078238 -0.00696" rpy="0 0 0"/>
    <mass value="2.145505324052611"/>
    <inertia ixx="0.0043236289419450735" iyy="0.002584036595369262" izz="0.0036071020257972194" ixy="-4.63384500729567e-06" iyz="-9.718705589953358e-08" ixz="2.5307575362242245e-07"/>
  </inertial>
  <visual>
    <origin xyz="-0.0 0.168 0.093" rpy="0 0 0"/>
    <geometry>
      <mesh filename="meshes/6_hip_R_1.stl" scale="0.001 0.001 0.001"/>
    </geometry>
    <material name="silver"/>
    <material/>
  </visual>
  <!-- <collision>
    <origin xyz="-0.0 0.168 0.093" rpy="0 0 0"/>
    <geometry>
      <mesh filename="meshes/6_hip_R_1.stl" scale="0.001 0.001 0.001"/>
    </geometry>
  </collision> -->
</link>

<link name="7_hip_R_1">
  <inertial>
    <origin xyz="-0.032881 0.019651 -0.188957" rpy="0 0 0"/>
    <mass value="3.718849744282159"/>
    <inertia ixx="0.027497143139293634" iyy="0.029358500822116718" izz="0.005306696738868154" ixy="0.00020545867257936107" iyz="0.0012624282912923196" ixz="-0.002425747983419498"/>
  </inertial>
  <visual>
    <origin xyz="-0.0272 0.0902 0.093" rpy="0 0 0"/>
    <geometry>
      <mesh filename="meshes/7_hip_R_1.stl" scale="0.001 0.001 0.001"/>
    </geometry>
    <material name="silver"/>
    <material/>
  </visual>
  <collision>
    <origin xyz="-0.0272 0.02 -0.205" rpy="0 0 0"/>
    <geometry>
      <box size="0.12 0.08 0.27"/>
    </geometry>
  </collision>
</link>

<link name="8_knee_R_1">
  <inertial>
    <origin xyz="0.020174 0.011965 -0.118449" rpy="0 0 0"/>
    <mass value="1.008967649963129"/>
    <inertia ixx="0.007304699903664141" iyy="0.009688584293469443" izz="0.002487274385998401" ixy="-8.906478202698942e-07" iyz="-2.7631243961649676e-05" ixz="0.0017826690415986435"/>
  </inertial>
  <visual>
    <origin xyz="-0.0 0.0829 0.373" rpy="0 0 0"/>
    <geometry>
      <mesh filename="meshes/8_knee_R_1.stl" scale="0.001 0.001 0.001"/>
    </geometry>
    <material name="silver"/>
    <material/>
  </visual>
  <!-- <collision>
    <origin xyz="-0.0 0.0829 0.373" rpy="0 0 0"/>
    <geometry>
      <mesh filename="meshes/8_knee_R_1.stl" scale="0.001 0.001 0.001"/>
    </geometry>
  </collision> -->
</link>

<link name="4_foot_L_simple_1">
  <inertial>
    <origin xyz="0.04057 0 -0.028042" rpy="0 0 0"/>
    <mass value="0.2422105"/>
    <inertia ixx="4.71711257565427e-05" iyy="0.00054163513919947" izz="0.0005455651932004392" ixy="0" iyz="0" ixz="1.0205724243504688e-05"/>
  </inertial>
  <visual>
    <origin xyz="-0.0 0.0902 0.608" rpy="0 0 0"/>
    <geometry>
      <mesh filename="meshes/9_foot_R_aug10_1.stl" scale="0.001 0.001 0.001"/>
    </geometry>
    <material name="silver"/>
    <material/>
  </visual>
  <collision>
    <origin xyz="-0.0 0.0902 0.608" rpy="0 0 0"/>
    <geometry>
      <mesh filename="meshes/9_foot_R_aug10_1.stl" scale="0.001 0.001 0.001"/>
    </geometry>
  </collision>
</link>


<joint name="body_to_imu" type="fixed">
  <origin xyz="0.0 0.0 -0.005" rpy="0 0 0"/>
  <parent link="base_link"/>
  <child link="body_1"/>
</joint>

<joint name="0_hip_L" type="revolute">
  <origin xyz="0.0 0.09 -0.0004" rpy="0 0 0"/>
  <parent link="body_1"/>
  <child link="0_hip_L_1"/>
  <axis xyz="0.0 0.0 -1.0"/>
  <limit upper="0.523599" lower="-1.047198" effort="81" velocity="13.333"/>
</joint>
<transmission name="0_hip_L_tran">
  <type>transmission_interface/SimpleTransmission</type>
  <joint name="0_hip_L">
    <hardwareInterface>PositionJointInterface</hardwareInterface>
  </joint>
  <actuator name="0_hip_L_actr">
    <hardwareInterface>PositionJointInterface</hardwareInterface>
    <mechanicalReduction>1</mechanicalReduction>
  </actuator>
</transmission>

<joint name="1_hip_L" type="revolute">
  <origin xyz="-0.0 0.078 -0.0876" rpy="0 0 0"/>
  <parent link="0_hip_L_1"/>
  <child link="1_hip_L_1"/>
  <axis xyz="0.0 -1.0 0.0"/>
  <limit upper="1.570796" lower="-1.570796" effort="90" velocity="12"/>
</joint>
<transmission name="1_hip_L_tran">
  <type>transmission_interface/SimpleTransmission</type>
  <joint name="1_hip_L">
    <hardwareInterface>PositionJointInterface</hardwareInterface>
  </joint>
  <actuator name="1_hip_L_actr">
    <hardwareInterface>PositionJointInterface</hardwareInterface>
    <mechanicalReduction>1</mechanicalReduction>
  </actuator>
</transmission>

<joint name="2_hip_L" type="revolute">
  <origin xyz="0.0272 -0.0778 0.0" rpy="0 0 0"/>
  <parent link="1_hip_L_1"/>
  <child link="2_hip_L_1"/>
  <axis xyz="1.0 0.0 -0.0"/>
  <limit upper="0.628319" lower="-0.628319" effort="81" velocity="13.333"/>
</joint>
<transmission name="2_hip_L_tran">
  <type>transmission_interface/SimpleTransmission</type>
  <joint name="2_hip_L">
    <hardwareInterface>PositionJointInterface</hardwareInterface>
  </joint>
  <actuator name="2_hip_L_actr">
    <hardwareInterface>PositionJointInterface</hardwareInterface>
    <mechanicalReduction>1</mechanicalReduction>
  </actuator>
</transmission>

<joint name="3_knee_L" type="revolute">
  <origin xyz="-0.0272 -0.0073 -0.28" rpy="0 0 0"/>
  <parent link="2_hip_L_1"/>
  <child link="3_knee_L_1"/>
  <axis xyz="0.0 1.0 0.0"/>
  <limit upper="1.570796" lower="0.0" effort="81" velocity="13.333"/>
</joint>
<transmission name="3_knee_L_tran">
  <type>transmission_interface/SimpleTransmission</type>
  <joint name="3_knee_L">
    <hardwareInterface>PositionJointInterface</hardwareInterface>
  </joint>
  <actuator name="3_knee_L_actr">
    <hardwareInterface>PositionJointInterface</hardwareInterface>
    <mechanicalReduction>1</mechanicalReduction>
  </actuator>
</transmission>

<joint name="4_foot_L" type="revolute">
  <origin xyz="0.0 0.0073 -0.235" rpy="0 0 0"/>
  <parent link="3_knee_L_1"/>
  <child link="4_foot_L_simple_1"/>
  <axis xyz="-0.0 1.0 0.0"/>
  <limit upper="0.785398" lower="-0.628319" effort="45" velocity="10.667"/>
</joint>
<transmission name="4_foot_L_tran">
  <type>transmission_interface/SimpleTransmission</type>
  <joint name="4_foot_L">
    <hardwareInterface>PositionJointInterface</hardwareInterface>
  </joint>
  <actuator name="4_foot_L_actr">
    <hardwareInterface>PositionJointInterface</hardwareInterface>
    <mechanicalReduction>1</mechanicalReduction>
  </actuator>
</transmission>


<joint name="5_hip_R" type="revolute">
  <origin xyz="-0.0 -0.09 -0.0004" rpy="0 0 0"/>
  <parent link="body_1"/>
  <child link="5_hip_R_1"/>
  <axis xyz="0.0 0.0 -1.0"/>
  <limit upper="1.047198" lower="-0.523599" effort="81" velocity="13.333"/>
</joint>
<transmission name="5_hip_R_tran">
  <type>transmission_interface/SimpleTransmission</type>
  <joint name="5_hip_R">
    <hardwareInterface>PositionJointInterface</hardwareInterface>
  </joint>
  <actuator name="5_hip_R_actr">
    <hardwareInterface>PositionJointInterface</hardwareInterface>
    <mechanicalReduction>1</mechanicalReduction>
  </actuator>
</transmission>

<joint name="6-hip_R" type="revolute">
  <origin xyz="0.0 -0.078 -0.0876" rpy="0 0 0"/>
  <parent link="5_hip_R_1"/>
  <child link="6_hip_R_1"/>
  <axis xyz="0.0 1.0 0.0"/>
  <limit upper="1.570796" lower="-1.570796" effort="90" velocity="12"/>
</joint>
<transmission name="6-hip_R_tran">
  <type>transmission_interface/SimpleTransmission</type>
  <joint name="6-hip_R">
    <hardwareInterface>PositionJointInterface</hardwareInterface>
  </joint>
  <actuator name="6-hip_R_actr">
    <hardwareInterface>PositionJointInterface</hardwareInterface>
    <mechanicalReduction>1</mechanicalReduction>
  </actuator>
</transmission>

<joint name="7_hip_R" type="revolute">
  <origin xyz="0.0272 0.0778 0.0" rpy="0 0 0"/>
  <parent link="6_hip_R_1"/>
  <child link="7_hip_R_1"/>
  <axis xyz="1.0 -0.0 0.0"/>
  <limit upper="0.628319" lower="-0.628319" effort="81" velocity="13.333"/>
</joint>
<transmission name="7_hip_R_tran">
  <type>transmission_interface/SimpleTransmission</type>
  <joint name="7_hip_R">
    <hardwareInterface>PositionJointInterface</hardwareInterface>
  </joint>
  <actuator name="7_hip_R_actr">
    <hardwareInterface>PositionJointInterface</hardwareInterface>
    <mechanicalReduction>1</mechanicalReduction>
  </actuator>
</transmission>

<joint name="8_knee_R" type="revolute">
  <origin xyz="-0.0272 0.0073 -0.28" rpy="0 0 0"/>
  <parent link="7_hip_R_1"/>
  <child link="8_knee_R_1"/>
  <axis xyz="-0.0 -1.0 0.0"/>
  <limit upper="0.0" lower="-1.570796" effort="81" velocity="13.333"/>
</joint>
<transmission name="8_knee_R_tran">
  <type>transmission_interface/SimpleTransmission</type>
  <joint name="8_knee_R">
    <hardwareInterface>PositionJointInterface</hardwareInterface>
  </joint>
  <actuator name="8_knee_R_actr">
    <hardwareInterface>PositionJointInterface</hardwareInterface>
    <mechanicalReduction>1</mechanicalReduction>
  </actuator>
</transmission>

<joint name="9_foot_R" type="revolute">
  <origin xyz="0.0 -0.0073 -0.235" rpy="0 0 0"/>
  <parent link="8_knee_R_1"/>
  <child link="9_foot_R_simple_1"/>
  <axis xyz="-0.0 -1.0 0.0"/>
  <limit upper="0.628319" lower="-0.785398" effort="45" velocity="10.667"/>
</joint>
<transmission name="9_foot_R_tran">
  <type>transmission_interface/SimpleTransmission</type>
  <joint name="9_foot_R">
    <hardwareInterface>PositionJointInterface</hardwareInterface>
  </joint>
  <actuator name="9_foot_R_actr">
    <hardwareInterface>PositionJointInterface</hardwareInterface>
    <mechanicalReduction>1</mechanicalReduction>
  </actuator>
</transmission>

</robot>
